2024-12-19 18:22:59,662 ERROR Error on request:
Traceback (most recent call last):
  File "D:\eunjiAi\projectEunji\python-modules\app.py", line 160, in update_daily_feedback
    entry = session.query(SquatFeedback).filter_by(uuid=uuid, squat_date=today).first()
  File "C:\Users\ict01-20\anaconda3\envs\py38\lib\site-packages\sqlalchemy\orm\query.py", line 2728, in first
    return self.limit(1)._iter().first()  # type: ignore
  File "C:\Users\ict01-20\anaconda3\envs\py38\lib\site-packages\sqlalchemy\orm\query.py", line 2827, in _iter
    result: Union[ScalarResult[_T], Result[_T]] = self.session.execute(
  File "C:\Users\ict01-20\anaconda3\envs\py38\lib\site-packages\sqlalchemy\orm\session.py", line 2362, in execute
    return self._execute_internal(
  File "C:\Users\ict01-20\anaconda3\envs\py38\lib\site-packages\sqlalchemy\orm\session.py", line 2237, in _execute_internal
    conn = self._connection_for_bind(bind)
  File "C:\Users\ict01-20\anaconda3\envs\py38\lib\site-packages\sqlalchemy\orm\session.py", line 2106, in _connection_for_bind
    return trans._connection_for_bind(engine, execution_options)
  File "<string>", line 2, in _connection_for_bind
  File "C:\Users\ict01-20\anaconda3\envs\py38\lib\site-packages\sqlalchemy\orm\state_changes.py", line 103, in _go
    self._raise_for_prerequisite_state(fn.__name__, current_state)
  File "C:\Users\ict01-20\anaconda3\envs\py38\lib\site-packages\sqlalchemy\orm\session.py", line 990, in _raise_for_prerequisite_state
    raise sa_exc.InvalidRequestError(
sqlalchemy.exc.InvalidRequestError: This session is provisioning a new connection; concurrent operations are not permitted (Background on this error at: https://sqlalche.me/e/20/isce)

During handling of the above exception, another exception occurred:

Traceback (most recent call last):
  File "C:\Users\ict01-20\anaconda3\envs\py38\lib\site-packages\werkzeug\debug\__init__.py", line 343, in debug_application
    app_iter = self.app(environ, start_response)
  File "C:\Users\ict01-20\anaconda3\envs\py38\lib\site-packages\flask\app.py", line 1498, in __call__
    return self.wsgi_app(environ, start_response)
  File "C:\Users\ict01-20\anaconda3\envs\py38\lib\site-packages\flask\app.py", line 1476, in wsgi_app
    response = self.handle_exception(e)
  File "C:\Users\ict01-20\anaconda3\envs\py38\lib\site-packages\flask_cors\extension.py", line 194, in wrapped_function
    return cors_after_request(app.make_response(f(*args, **kwargs)))
  File "C:\Users\ict01-20\anaconda3\envs\py38\lib\site-packages\flask\app.py", line 1473, in wsgi_app
    response = self.full_dispatch_request()
  File "C:\Users\ict01-20\anaconda3\envs\py38\lib\site-packages\flask\app.py", line 882, in full_dispatch_request
    rv = self.handle_user_exception(e)
  File "C:\Users\ict01-20\anaconda3\envs\py38\lib\site-packages\flask_cors\extension.py", line 194, in wrapped_function
    return cors_after_request(app.make_response(f(*args, **kwargs)))
  File "C:\Users\ict01-20\anaconda3\envs\py38\lib\site-packages\flask\app.py", line 880, in full_dispatch_request
    rv = self.dispatch_request()
  File "C:\Users\ict01-20\anaconda3\envs\py38\lib\site-packages\flask\app.py", line 865, in dispatch_request
    return self.ensure_sync(self.view_functions[rule.endpoint])(**view_args)  # type: ignore[no-any-return]
  File "D:\eunjiAi\projectEunji\python-modules\app.py", line 202, in squat_analysis
    update_daily_feedback(uuid, result.get('feedback') == "���� �Ϸ�")  # Update the feedback in DB
  File "D:\eunjiAi\projectEunji\python-modules\app.py", line 180, in update_daily_feedback
    session.rollback()  # ���� �߻� �� ���� �ѹ�
  File "C:\Users\ict01-20\anaconda3\envs\py38\lib\site-packages\sqlalchemy\orm\session.py", line 1990, in rollback
    self._transaction.rollback(_to_root=True)
  File "<string>", line 2, in rollback
  File "C:\Users\ict01-20\anaconda3\envs\py38\lib\site-packages\sqlalchemy\orm\state_changes.py", line 103, in _go
    self._raise_for_prerequisite_state(fn.__name__, current_state)
  File "C:\Users\ict01-20\anaconda3\envs\py38\lib\site-packages\sqlalchemy\orm\session.py", line 990, in _raise_for_prerequisite_state
    raise sa_exc.InvalidRequestError(
sqlalchemy.exc.InvalidRequestError: This session is provisioning a new connection; concurrent operations are not permitted (Background on this error at: https://sqlalche.me/e/20/isce)

During handling of the above exception, another exception occurred:

Traceback (most recent call last):
  File "C:\Users\ict01-20\anaconda3\envs\py38\lib\site-packages\werkzeug\serving.py", line 370, in run_wsgi
    execute(self.server.app)
  File "C:\Users\ict01-20\anaconda3\envs\py38\lib\site-packages\werkzeug\serving.py", line 333, in execute
    for data in application_iter:
  File "C:\Users\ict01-20\anaconda3\envs\py38\lib\site-packages\werkzeug\debug\__init__.py", line 378, in debug_application
    environ["wsgi.errors"].write("".join(tb.render_traceback_text()))
OSError: [WinError 6] �ڵ��� �߸��Ǿ����ϴ�
2024-12-19 18:22:59,662 ERROR Error on request:
Traceback (most recent call last):
  File "D:\eunjiAi\projectEunji\python-modules\app.py", line 160, in update_daily_feedback
    entry = session.query(SquatFeedback).filter_by(uuid=uuid, squat_date=today).first()
  File "C:\Users\ict01-20\anaconda3\envs\py38\lib\site-packages\sqlalchemy\orm\query.py", line 2728, in first
    return self.limit(1)._iter().first()  # type: ignore
  File "C:\Users\ict01-20\anaconda3\envs\py38\lib\site-packages\sqlalchemy\orm\query.py", line 2827, in _iter
    result: Union[ScalarResult[_T], Result[_T]] = self.session.execute(
  File "C:\Users\ict01-20\anaconda3\envs\py38\lib\site-packages\sqlalchemy\orm\session.py", line 2362, in execute
    return self._execute_internal(
  File "C:\Users\ict01-20\anaconda3\envs\py38\lib\site-packages\sqlalchemy\orm\session.py", line 2237, in _execute_internal
    conn = self._connection_for_bind(bind)
  File "C:\Users\ict01-20\anaconda3\envs\py38\lib\site-packages\sqlalchemy\orm\session.py", line 2106, in _connection_for_bind
    return trans._connection_for_bind(engine, execution_options)
  File "<string>", line 2, in _connection_for_bind
  File "C:\Users\ict01-20\anaconda3\envs\py38\lib\site-packages\sqlalchemy\orm\state_changes.py", line 103, in _go
    self._raise_for_prerequisite_state(fn.__name__, current_state)
  File "C:\Users\ict01-20\anaconda3\envs\py38\lib\site-packages\sqlalchemy\orm\session.py", line 990, in _raise_for_prerequisite_state
    raise sa_exc.InvalidRequestError(
sqlalchemy.exc.InvalidRequestError: This session is provisioning a new connection; concurrent operations are not permitted (Background on this error at: https://sqlalche.me/e/20/isce)

During handling of the above exception, another exception occurred:

Traceback (most recent call last):
  File "C:\Users\ict01-20\anaconda3\envs\py38\lib\site-packages\werkzeug\debug\__init__.py", line 343, in debug_application
    app_iter = self.app(environ, start_response)
  File "C:\Users\ict01-20\anaconda3\envs\py38\lib\site-packages\flask\app.py", line 1498, in __call__
    return self.wsgi_app(environ, start_response)
  File "C:\Users\ict01-20\anaconda3\envs\py38\lib\site-packages\flask\app.py", line 1476, in wsgi_app
    response = self.handle_exception(e)
  File "C:\Users\ict01-20\anaconda3\envs\py38\lib\site-packages\flask_cors\extension.py", line 194, in wrapped_function
    return cors_after_request(app.make_response(f(*args, **kwargs)))
  File "C:\Users\ict01-20\anaconda3\envs\py38\lib\site-packages\flask\app.py", line 1473, in wsgi_app
    response = self.full_dispatch_request()
  File "C:\Users\ict01-20\anaconda3\envs\py38\lib\site-packages\flask\app.py", line 882, in full_dispatch_request
    rv = self.handle_user_exception(e)
  File "C:\Users\ict01-20\anaconda3\envs\py38\lib\site-packages\flask_cors\extension.py", line 194, in wrapped_function
    return cors_after_request(app.make_response(f(*args, **kwargs)))
  File "C:\Users\ict01-20\anaconda3\envs\py38\lib\site-packages\flask\app.py", line 880, in full_dispatch_request
    rv = self.dispatch_request()
  File "C:\Users\ict01-20\anaconda3\envs\py38\lib\site-packages\flask\app.py", line 865, in dispatch_request
    return self.ensure_sync(self.view_functions[rule.endpoint])(**view_args)  # type: ignore[no-any-return]
  File "D:\eunjiAi\projectEunji\python-modules\app.py", line 202, in squat_analysis
    update_daily_feedback(uuid, result.get('feedback') == "���� �Ϸ�")  # Update the feedback in DB
  File "D:\eunjiAi\projectEunji\python-modules\app.py", line 180, in update_daily_feedback
    session.rollback()  # ���� �߻� �� ���� �ѹ�
  File "C:\Users\ict01-20\anaconda3\envs\py38\lib\site-packages\sqlalchemy\orm\session.py", line 1990, in rollback
    self._transaction.rollback(_to_root=True)
  File "<string>", line 2, in rollback
  File "C:\Users\ict01-20\anaconda3\envs\py38\lib\site-packages\sqlalchemy\orm\state_changes.py", line 103, in _go
    self._raise_for_prerequisite_state(fn.__name__, current_state)
  File "C:\Users\ict01-20\anaconda3\envs\py38\lib\site-packages\sqlalchemy\orm\session.py", line 990, in _raise_for_prerequisite_state
    raise sa_exc.InvalidRequestError(
sqlalchemy.exc.InvalidRequestError: This session is provisioning a new connection; concurrent operations are not permitted (Background on this error at: https://sqlalche.me/e/20/isce)

During handling of the above exception, another exception occurred:

Traceback (most recent call last):
  File "C:\Users\ict01-20\anaconda3\envs\py38\lib\site-packages\werkzeug\serving.py", line 370, in run_wsgi
    execute(self.server.app)
  File "C:\Users\ict01-20\anaconda3\envs\py38\lib\site-packages\werkzeug\serving.py", line 333, in execute
    for data in application_iter:
  File "C:\Users\ict01-20\anaconda3\envs\py38\lib\site-packages\werkzeug\debug\__init__.py", line 378, in debug_application
    environ["wsgi.errors"].write("".join(tb.render_traceback_text()))